Workbook

Sheet Arkusz1
B1: Donald Tusk | C1: Rafał Trzaskowski | D1: Szymon Hołownia | E1: Sławomir Mentzen | F1: Jarosław Kaczyński | G1: Władysław Kosiniak-Kamysz | H1: Karol Nawrocki | I1: Adrian Zandberg | J1: Polityk Idealny
A2: Uczciwy | B2: 39.428571 | C2: 44.646154 | D2: 46.685714 | E2: 34.323077 | F2: 27.938462 | G2: 40.582418 | H2: 32.123077 | I2: 46.424176 | J2: 90.973626
A3: Wiarygodny | B3: 39.523077 | C3: 44.325275 | D3: 42.824176 | E3: 32.918681 | F3: 28.912088 | G3: 39.707692 | H3: 30.716484 | I3: 43.945055 | J3: 90.771429
A4: Kompetentny | B4: 54.591209 | C4: 53.101099 | D4: 46.397802 | E4: 37.525275 | F4: 37.874725 | G4: 42.734066 | H4: 32.375824 | I4: 43.035165 | J4: 90.789011
A5: Konsekwentny | B5: 45.437363 | C5: 46.556044 | D5: 45.052747 | E5: 42.865934 | F5: 47.87033 | G5: 40.556044 | H5: 36.103297 | I5: 46.18022 | J5: 88.72967
A6: Charyzmatyczny | B6: 51.947253 | C6: 54.964835 | D6: 55.553846 | E6: 41.606593 | F6: 33.498901 | G6: 37.356044 | H6: 33 | I6: 45.226374 | J6: 84.215385
A7: Komunikatywny | B7: 55.050549 | C7: 61.426374 | D7: 63.549451 | E7: 41.465934 | F7: 30.169231 | G7: 44.112088 | H7: 36.6 | I7: 49.6 | J7: 88.769231
A8: Kulturalny | B8: 56.424176 | C8: 62.465934 | D8: 61.263736 | E8: 38.151648 | F8: 29.292308 | G8: 53.727473 | H8: 41.718681 | I8: 53.362637 | J8: 87.153846
A9: Lojalny | B9: 46.676923 | C9: 50.740659 | D9: 48.301099 | E9: 41.881319 | F9: 47.391209 | G9: 45.015385 | H9: 42.931868 | I9: 47.654945 | J9: 86.806593
A10: Odpowiedzialny | B10: 48.193407 | C10: 51.114286 | D10: 49.861538 | E10: 36.602198 | F10: 34.975824 | G10: 44.885714 | H10: 35.547253 | I10: 45.472527 | J10: 90.991209
A11: Medialny | B11: 61.312088 | C11: 66.971429 | D11: 69.525275 | E11: 53.850549 | F11: 32.553846 | G11: 42.421978 | H11: 38.934066 | I11: 49.30989 | J11: 80.032967
A12: Innowacyjny | B12: 42.784615 | C12: 51.5 | D12: 50.206593 | E12: 41.778022 | F12: 23.131868 | G12: 36.648352 | H12: 30.542857 | I12: 48.054945 | J12: 81.36044
A13: Tolerancyjny | B13: 53.536264 | C13: 64.09011 | D13: 54.586813 | E13: 24.105495 | F13: 19.652747 | G13: 42.010989 | H13: 28.991209 | I13: 59.553846 | J13: 81.597802
... A18: Atrakcyjny | B18: 35.67033 | C18: 60.789011 | D18: 43.87033 | E18: 36.672527 | F18: 18.243956 | G18: 40.112088 | H18: 32.410989 | I18: 39.804396 | J18: 64.824176

Sheet Arkusz2
C2: ŚREDNIA OCEN | D2: NAJNIŻSZA ŚREDNIA OCENA | E2: CECHA | F2: NAJWYŻSZA ŚREDNIA OCENA | G2: CECHA | L2: CECHA | M2: POLITYK Z NAJNIŻSZĄ ŚREDNIĄ OCENĄ CECHY | N2: POLITYK Z NAJWYŻSZĄ ŚREDNIĄ OCENĄ CECHY
B3: Donald Tusk | C3: =AVERAGE(Arkusz1!B2:B18) -> 50.498643 | D3: 35.67033 | E3: Atrakcyjny | F3: 66.169231 | G3: Wpływowy | L3: Uczciwy | M3: Jarosław Kaczyński | N3: Szymon Hołownia
B4: Rafał Trzaskowski | C4: =AVERAGE(Arkusz1!C2:C18) -> 55.283064 | D4: 44.325275 | E4: Wiarygodny | F4: 66.971429 | G4: Medialny | L4: Wiarygodny | M4: Jarosław Kaczyński | N4: Rafał Trzaskowski
B5: Szymon Hołownia | C5: =AVERAGE(Arkusz1!D2:D18) -> 52.08468 | D5: 42.824176 | E5: Wiarygodny | F5: 69.525275 | G5: Medialny | L5: Kompetentny | M5: Karol Nawrocki | N5: Donald Tusk
B6: Sławomir Mentzen | C6: =AVERAGE(Arkusz1!E2:E18) -> 38.455591 | D6: 24.105495 | E6: Tolerancyjny | F6: 53.850549 | G6: Medialny | L6: Konsekwentny | M6: Karol Nawrocki | N6: Jarosław Kaczyński
B7: Jarosław Kaczyński | C7: =AVERAGE(Arkusz1!F2:F18) -> 33.238268 | D7: 18.243956 | E7: Atrakcyjny | F7: 56.632967 | G7: Wpływowy | L7: Charyzmatyczny | M7: Karol Nawrocki | N7: Szymon Hołownia
B8: Władysław Kosiniak-Kamysz | C8: =AVERAGE(Arkusz1!G2:G18) -> 42.565999 | D8: 36.648352 | E8: Innowacyjny | F8: 53.727473 | G8: Kulturalny | L8: Komunikatywny | M8: Jarosław Kaczyński | N8: Rafał Trzaskowski
B9: Karol Nawrocki | C9: =AVERAGE(Arkusz1!H2:H18) -> 34.571558 | D9: 28.991209 | E9: Tolerancyjny | F9: 42.931868 | G9: Lojalny | L9: Kulturalny | M9: Jarosław Kaczyński | N9: Rafał Trzaskowski
B10: Adrian Zandberg | C10: =AVERAGE(Arkusz1!I2:I18) -> 46.567292 | D10: 36.536264 | E10: Wpływowy | F10: 59.553846 | G10: Tolerancyjny | L10: Lojalny | M10: Sławomir Mentzen | N10: Rafał Trzaskowski
B11: Polityk Idealny | C11: =AVERAGE(Arkusz1!J2:J18) -> 85.629606 | D11: 64.824176 | E11: Atrakcyjny | F11: 90.991209 | G11: Odpowiedzialny | L11: Odpowiedzialny | M11: Jarosław Kaczyński | N11: Rafał Trzaskowski
L12: Medialny | M12: Jarosław Kaczyński | N12: Szymon Hołownia
L13: Innowacyjny | M13: Jarosław Kaczyński | N13: Rafał Trzaskowski
L14: Tolerancyjny | M14: Jarosław Kaczyński | N14: Rafał Trzaskowski
A15: MAX | B15: =MAX(Arkusz1!B2:B18) -> 66.169231 | C15: =MAX(Arkusz1!C2:C18) -> 66.971429 | D15: =MAX(Arkusz1!D2:D18) -> 69.525275 | E15: =MAX(Arkusz1!E2:E18) -> 53.850549 | F15: =MAX(Arkusz1!F2:F18) -> 56.632967 | G15: =MAX(Arkusz1!G2:G18) -> 53.727473 | H15: =MAX(Arkusz1!H2:H18) -> 42.931868 | I15: =MAX(Arkusz1!I2:I18) -> 59.553846 | J15: =MAX(Arkusz1!J2:J18) -> 90.991209 | L15: Dyplomatyczny | M15: Jarosław Kaczyński | N15: Rafał Trzaskowski
A16: MIN | B16: =MIN(Arkusz1!B2:B18) -> 35.67033 | C16: =MIN(Arkusz1!C2:C18) -> 44.325275 | D16: =MIN(Arkusz1!D2:D18) -> 42.824176 | E16: =MIN(Arkusz1!E2:E18) -> 24.105495 | F16: =MIN(Arkusz1!F2:F18) -> 18.243956 | G16: =MIN(Arkusz1!G2:G18) -> 36.648352 | H16: =MIN(Arkusz1!H2:H18) -> 28.991209 | I16: =MIN(Arkusz1!I2:I18) -> 36.536264 | J16: =MIN(Arkusz1!J2:J18) -> 64.824176 | L16: Szanowany | M16: Karol Nawrocki | N16: Rafał Trzaskowski
L17: Elokwentny | M17: Jarosław Kaczyński | N17: Rafał Trzaskowski
L18: Wpływowy | M18: Karol Nawrocki | N18: Donald Tusk
L19: Atrakcyjny | M19: Jarosław Kaczyński | N19: Rafał Trzaskowski

Sheet Arkusz3
C2: Donald Tusk | D2: Rafał Trzaskowski | E2: Szymon Hołownia | F2: Sławomir Mentzen | G2: Jarosław Kaczyński | H2: Władysław Kosiniak-Kamysz | I2: Karol Nawrocki | J2: Adrian Zandberg | K2: Polityk Idealny | L2: SUMY WZGLĘDNE | Q2: Donald Tusk | R2: Rafał Trzaskowski | S2: Szymon Hołownia | T2: Sławomir Mentzen | U2: Jarosław Kaczyński | V2: Władysław Kosiniak-Kamysz | W2: Karol Nawrocki | X2: Adrian Zandberg | Y2: Polityk Idealny
B3: Uczciwy | C3: 0.09780724 | D3: 0.1107501 | E3: 0.1158094 | F3: 0.08514246 | G3: 0.06930466 | H3: 0.10066949 | I3: 0.0796851 | J3: 0.11516067 | K3: 0.2256709 | L3: 0.05402948 | P3: [1,] | Q3: 0.09780724 | R3: 0.1107501 | S3: 0.1158094 | T3: 0.08514246 | U3: 0.06930466 | V3: 0.10066949 | W3: 0.0796851 | X3: 0.11516067 | Y3: 0.2256709
B4: Wiarygodny | C4: 0.10040311 | D4: 0.1126025 | E4: 0.1087891 | F4: 0.08362552 | G4: 0.07344731 | H4: 0.1008721 | I4: 0.07803113 | J4: 0.11163655 | K4: 0.2305927 | L4: 0.05275873 | P4: [2,] | Q4: 0.10040311 | R4: 0.1126025 | S4: 0.1087891 | T4: 0.08362552 | U4: 0.07344731 | V4: 0.1008721 | W4: 0.07803113 | X4: 0.11163655 | Y4: 0.2305927
B5: Kompetentny | C5: 0.12451688 | D5: 0.1211181 | E5: 0.1058286 | F5: 0.08559125 | G5: 0.08638831 | H5: 0.09747197 | I5: 0.07384589 | J5: 0.09815874 | K5: 0.2070803 | L5: 0.05876047 | P5: [3,] | Q5: 0.12451688 | R5: 0.1211181 | S5: 0.1058286 | T5: 0.08559125 | U5: 0.08638831 | V5: 0.09747197 | W5: 0.07384589 | X5: 0.09815874 | Y5: 0.2070803
B6: Konsekwentny | C6: 0.10341912 | D6: 0.1059653 | E6: 0.1025437 | F6: 0.09756634 | G6: 0.10895675 | H6: 0.09230885 | I6: 0.08217403 | J6: 0.10510993 | K6: 0.2019559 | L6: 0.05888477 | P6: [4,] | Q6: 0.10341912 | R6: 0.1059653 | S6: 0.1025437 | T6: 0.09756634 | U6: 0.10895675 | V6: 0.09230885 | W6: 0.08217403 | X6: 0.10510993 | Y6: 0.2019559
B7: Charyzmatyczny | C7: 0.11877208 | D7: 0.1256715 | E7: 0.1270182 | F7: 0.09512922 | G7: 0.07659181 | H7: 0.08541077 | I7: 0.07545112 | J7: 0.10340548 | K7: 0.1925499 | L7: 0.05861908 | P7: [5,] | Q7: 0.11877208 | R7: 0.1256715 | S7: 0.1270182 | T7: 0.09512922 | U7: 0.07659181 | V7: 0.08541077 | W7: 0.07545112 | X7: 0.10340548 | Y7: 0.1925499
B8: Komunikatywny | C8: 0.11694399 | D8: 0.1304882 | E8: 0.1349982 | F8: 0.08808617 | G8: 0.06408856 | H8: 0.0937074 | I8: 0.07774945 | J8: 0.10536538 | K8: 0.1885727 | L8: 0.06309203 | P8: [6,] | Q8: 0.11694399 | R8: 0.1304882 | S8: 0.1349982 | T8: 0.08808617 | U8: 0.06408856 | V8: 0.0937074 | W8: 0.07774945 | X8: 0.10536538 | Y8: 0.1885727
B9: Kulturalny | C9: 0.11668485 | D9: 0.1291792 | E9: 0.126693 | F9: 0.07889737 | G9: 0.06057631 | H9: 0.11110808 | I9: 0.08627398 | J9: 0.1103536 | K9: 0.1802336 | L9: 0.06480992 | P9: [7,] | Q9: 0.11668485 | R9: 0.1291792 | S9: 0.126693 | T9: 0.07889737 | U9: 0.06057631 | V9: 0.11110808 | W9: 0.08627398 | X9: 0.1103536 | Y9: 0.1802336
B10: Lojalny | C10: 0.10204837 | D10: 0.1109328 | E10: 0.1055993 | F10: 0.09156388 | G10: 0.10360999 | H10: 0.09841579 | I10: 0.09386066 | J10: 0.10418659 | K10: 0.1897827 | L10: 0.06130373 | P10: [8,] | Q10: 0.10204837 | R10: 0.1109328 | S10: 0.1055993 | T10: 0.09156388 | U10: 0.10360999 | V10: 0.09841579 | W10: 0.09386066 | X10: 0.10418659 | Y10: 0.1897827
B11: Odpowiedzialny | C11: 0.11012012 | D11: 0.1167942 | E11: 0.1139317 | F11: 0.08363465 | G11: 0.07991844 | H11: 0.10256217 | I11: 0.08122414 | J11: 0.10390302 | K11: 0.2079115 | L11: 0.0586559 | P11: [9,] | Q11: 0.11012012 | R11: 0.1167942 | S11: 0.1139317 | T11: 0.08363465 | U11: 0.07991844 | V11: 0.10256217 | W11: 0.08122414 | X11: 0.10390302 | Y11: 0.2079115
B12: Medialny | C12: 0.12388481 | D12: 0.1353198 | E12: 0.14048 | F12: 0.10880831 | G12: 0.06577703 | H12: 0.08571619 | I12: 0.07866865 | J12: 0.09963363 | K12: 0.1617115 | L12: 0.06633135 | P12: [10,] | Q12: 0.12388481 | R12: 0.1353198 | S12: 0.14048 | T12: 0.10880831 | U12: 0.06577703 | V12: 0.08571619 | W12: 0.07866865 | X12: 0.09963363 | Y12: 0.1617115
B13: Innowacyjny | C13: 0.10537883 | D13: 0.1268449 | E13: 0.1236592 | F13: 0.10289958 | G13: 0.05697397 | H13: 0.09026517 | I13: 0.07522729 | J13: 0.11835969 | K13: 0.2003914 | L13: 0.0544158 | P13: [11,] | Q13: 0.10537883 | R13: 0.1268449 | S13: 0.1236592 | T13: 0.10289958 | U13: 0.05697397 | V13: 0.09026517 | W13: 0.07522729 | X13: 0.11835969 | Y13: 0.2003914
B14: Tolerancyjny | C14: 0.12504813 | D14: 0.1496994 | E14: 0.127502 | F14: 0.05630477 | G14: 0.0459042 | H14: 0.09812779 | I14: 0.06771665 | J14: 0.13910378 | K14: 0.1905933 | L14: 0.05738014 | P14: [12,] | Q14: 0.12504813 | R14: 0.1496994 | S14: 0.127502 | T14: 0.05630477 | U14: 0.0459042 | V14: 0.09812779 | W14: 0.06771665 | X14: 0.13910378 | Y14: 0.1905933
... B19: Atrakcyjny | C19: 0.09578555 | D19: 0.1632368 | E19: 0.117805 | F19: 0.09847676 | G19: 0.0489905 | H19: 0.10771301 | I19: 0.08703324 | J19: 0.10688676 | K19: 0.1740724 | L19: 0.04991118 | P19: [17,] | Q19: 0.09578555 | R19: 0.1632368 | S19: 0.117805 | T19: 0.09847676 | U19: 0.0489905 | V19: 0.10771301 | W19: 0.08703324 | X19: 0.10688676 | Y19: 0.1740724
B20: SUMY WZGLĘDNE | C20: 0.11505867 | D20: 0.12595974 | E20: 0.11867238 | F20: 0.087619175 | G20: 0.075731759 | H20: 0.096984536 | I20: 0.078769595 | J20: 0.10610129 | K20: 0.19510285 | L20: 1

Sheet Arkusz4
B2: POLITYCY | C2: WSPÓŁRZĘDNE PIERWSZEGO WYMIARU | D2: WSPÓŁRZĘDNE DRUGIEGO WYMIARU | E2: MASY | F2: JAKOŚĆ | G2: WZGLĘDNA BEZWŁADNOŚĆ | H2: WYMIAR 1 | J2: WYMIAR 2
H3: BEZWŁADNOŚĆ | I3: COS2 | J3: BEZWŁADNOŚĆ | K3: COS2
B4: Donald Tusk | C4: 0.018483292 | D4: -0.07533871 | E4: 0.11505867 | F4: 0.4869651 | G4: 9.594835 | H4: 0.49258164 | I4: 0.027646274 | J4: 23.811598 | K4: 0.45931882
B5: Rafał Trzaskowski | C5: -0.084374737 | D5: -0.04424734 | E5: 0.12595974 | F5: 0.78108249 | G5: 9.878014 | H5: 11.237166 | I5: 0.61260862 | J5: 8.991641 | K5: 0.16847387
B6: Szymon Hołownia | C6: -0.075096048 | D6: -0.04117605 | E6: 0.11867238 | F6: 0.78327994 | G6: 7.499322 | H6: 8.3865629 | I6: 0.60222382 | J6: 7.336214 | K6: 0.18105612 | U6: [1,] | V6: -0.007311635 | W6: 0.097493353 | X6: 0.014600237 | Y6: 0.0299333963 | Z6: 0.008344512 | AA6: 0.008503530 | AB6: 0.0030382372 | AC6: -0.0015520669
B7: Sławomir Mentzen | C7: 0.028249144 | D7: -0.04588858 | E7: 0.08761917 | F7: 0.16224026 | G7: 10.582777 | H7: 0.87621346 | I7: 0.044586786 | J7: 6.727306 | K7: 0.11765348 | U7: [2,] | V7: 0.013613197 | W7: 0.10021348 | X7: 0.001217389 | Y7: 0.0243759586 | Z7: 0.019749480 | AA7: -0.006754162 | AB7: 0.0015719998 | AC7: 0.0016254768
B8: Jarosław Kaczyński | C8: 0.26934972 | D8: -0.01906087 | E8: 0.07573176 | F8: 0.9853405 | G8: 37.817285 | H8: 68.851167 | I8: 0.98043064 | J8: 1.003221 | K8: 0.004909863 | U8: [3,] | V8: 0.058504734 | W8: 0.0052827726 | X8: -0.031855763 | Y8: 0.0045494531 | Z8: 0.024952804 | AA8: -0.015478885 | AB8: -0.0134650086 | AC8: 0.0032378140
B9: Władysław Kosiniak-Kamysz | C9: -0.026419037 | D9: 0.04015487 | E9: 0.09698454 | F9: 0.4050697 | G9: 3.732949 | H9: 0.84827498 | I9: 0.12237156 | J9: 5.701798 | K9: 0.28269814 | U9: [4,] | V9: 0.13768457 | W9: 0.031408718 | X9: 0.039833973 | Y9: 0.0011113566 | Z9: -0.034646337 | AA9: -0.009858956 | AB9: -0.0026000612 | AC9: -0.0059805409
B10: Karol Nawrocki | C10: 0.005172374 | D10: 0.01948431 | E10: 0.0787696 | F10: 0.064346006 | G10: 3.357207 | H10: 0.02640819 | I10: 0.004236005 | J10: 1.090339 | K10: 0.060110001 | U10: [5,] | V10: 0.003828192 | W10: -0.034735644 | X10: 0.013639035 | Y10: 0.0372814763 | Z10: -0.003954029 | AA10: -0.001704859 | AB10: 0.0121388378 | AC10: 0.0045537282
B11: Adrian Zandberg | C11: -0.076551286 | D11: 0.05145735 | E11: 0.10610128 | F11: 0.73040592 | G11: 8.340225 | H11: 7.7915851 | I11: 0.50308798 | J11: 10.243498 | K11: 0.22731794 | U11: [6,] | V11: -0.05283433 | W11: -0.027919461 | X11: 0.004816328 | Y11: 0.0181712398 | Z11: 0.004020628 | AA11: 0.019205776 | AB11: 0.0161683537 | AC11: -0.0030037024
B12: Polityk Idealny | C12: 0.024686933 | D12: 0.07023775 | E12: 0.19510285 | F12: 0.79345703 | G12: 9.197386 | H12: 1.4900406 | I12: 0.087242798 | J12: 35.094386 | K12: 0.70621423 | U12: [7,] | V12: -0.069397439 | W12: -0.0003501511 | X12: -0.009825320 | Y12: -0.0424382403 | Z12: -0.000852683 | AA12: 0.041146079 | AB12: -0.0143255158 | AC12: -0.0033448417
U13: [8,] | V13: 0.10841834 | W13: 0.025783606 | X13: 0.044178899 | Y13: -0.0447275825 | Z13: -0.038848791 | AA13: 0.016147550 | AB13: 0.0032309641 | AC13: 0.0091641858
U14: [9,] | V14: 0.026900218 | W14: 0.04075196 | X14: -0.003222153 | Y14: -0.0057861982 | Z14: 0.012757415 | AA14: 0.012963172 | AB14: 0.0007038357 | AC14: -0.0022665444
U15: [10,] | V15: -0.049020931 | W15: -0.11251157 | X15: 0.057139634 | Y15: 0.0260551569 | Z15: -0.006623947 | AA15: 0.013266366 | AB15: -0.0022723624 | AC15: 0.0007143482
U16: [11,] | V16: -0.06601865 | W16: 0.015362039 | X16: 0.050976005 | Y16: 0.0508757740 | Z16: -0.005788720 | AA16: -0.021704007 | AB16: -0.0149123899 | AC16: 0.0041475015
U17: [12,] | V17: -0.15812281 | W17: 0.020067991 | X17: -0.111491902 | Y17: -0.0008250948 | Z17: -0.050581967 | AA17: -0.021585951 | AB17: 0.0030982789 | AC17: -0.0010227868
U18: [13,] | V18: -0.046455857 | W18: -0.017664367 | X18: -0.062867452 | Y18: -0.0086479965 | Z18: 0.023795881 | AA18: 0.016510255 | AB18: -0.0006203812 | AC18: 0.0091695092
U19: [14,] | V19: 0.044015007 | W19: 0.018075538 | X19: -0.007838293 | Y19: -0.0223632307 | Z19: 0.025790568 | AA19: 0.001363733 | AB19: 0.0118120865 | AC19: -0.0039782560
B20: Donald Tusk | C20: 0.018483292 | D20: -0.07533871 | E20: -0.076495975 | F20: 0.01422704 | G20: 0.008741341 | H20: 0.008481786 | I20: -0.010938895 | J20: 0.0042011731 | U20: [15,] | V20: -0.035882716 | W20: -0.021485937 | X20: 0.009328756 | Y20: 0.0054586881 | Z20: 0.002380214 | AA20: 0.001324297 | AB20: -0.0054984573 | AC20: -0.0093689508
B21: Rafał Trzaskowski | C21: -0.084374737 | D21: -0.04424734 | E21: -0.010121932 | F21: -0.03200441 | G21: 0.004441043 | H21: -0.036384047 | I21: 0.008587418 | J21: 0.0001707904 | U21: [16,] | V21: 0.20169273 | W21: -0.083367369 | X21: -0.070996039 | Y21: -0.0011871954 | Z21: 0.005349838 | AA21: -0.019805067 | AB21: -0.0013495825 | AC21: -0.0018436568
B22: Szymon Hołownia | C22: -0.075096048 | D22: -0.04117605 | E22: 0.010525209 | F22: 0.02628464 | G22: -0.005092438 | H22: 0.032229856 | I22: 0.011928409 | J22: -0.0045596361 | U22: [17,] | V22: -0.12484384 | W22: -0.019001499 | X22: 0.070741041 | Y22: -0.0731359220 | Z22: 0.020187585 | AA22: -0.051500126 | AB22: 0.0045661915 | AC22: 0.0003678533
B23: Sławomir Mentzen | C23: 0.028249144 | D23: -0.04588858 | E23: 0.117039537 | F23: 0.02937765 | G23: 0.009391065 | H23: -0.015047283 | I23: -0.010851011 | J23: -0.0007504779
B24: Jarosław Kaczyński | C24: 0.26934972 | D24: -0.01906087 | E24: -0.010208753 | F24: -0.01664275 | G24: -0.024923918 | H24: -0.004468456 | I24: 0.006815988 | J24: -0.0039922517
B25: Władysław Kosiniak-Kamysz | C25: -0.026419037 | D25: 0.04015487 | E25: -0.005146055 | F25: -0.05052224 | G25: 0.019918447 | H25: 0.015262109 | I25: -0.010761175 | J25: -0.0082958478 | U25: [1,] | V25: 0.004940317 | W25: 0.8783666 | X25: 0.0196990633 | Y25: 8.280142e-02 | Z25: 6.434691e-03 | AA25: 0.0066822746 | AB25: 8.530395e-04 | AC25: 2.226110e-04
B26: Karol Nawrocki | C26: 0.005172374 | D26: 0.01948431 | E26: 0.051731864 | F26: -0.04744749 | G26: -0.006332905 | H26: 0.028209576 | I26: 0.003051501 | J26: 0.0116913689 | U26: [2,] | V26: 0.016451602 | W26: 0.8915387 | X26: 0.0001315668 | Y26: 5.274865e-02 | Z26: 3.462576e-02 | AA26: 0.0040497746 | AB26: 2.193779e-04 | AC26: 2.345576e-04
B27: Adrian Zandberg | C27: -0.076551286 | D27: 0.05145735 | E27: -0.012812215 | F27: 0.01325695 | G27: -0.051651454 | H27: -0.008786696 | I27: -0.007434598 | J27: -0.0002244453 | U27: [3,] | V27: 0.61780933 | W27: 0.005037282 | X27: 0.1831675192 | Y27: 3.735862e-03 | Z27: 1.123857e-01 | AA27: 0.0432465815 | AB27: 3.272546e-02 | AC27: 1.892240e-03
B28: Polityk Idealny | C28: 0.024686933 | D28: 0.07023775 | E28: -0.014714131 | F28: 0.02661220 | G28: 0.021277042 | H28: -0.006821545 | I28: 0.004039231 | J28: 0.0015979457 | U28: [4,] | V28: 0.82884543 | W28: 0.04313238 | X28: 0.0693761590 | Y28: 5.400200e-05 | Z28: 5.248288e-02 | AA28: 0.0042497648 | AB28: 2.955767e-04 | AC28: 1.563810e-03
U29: [5,] | V29: 0.004911571 | W29: 0.4043746 | X29: 0.0623448260 | Y29: 4.658213e-01 | Z29: 5.239778e-03 | AA29: 0.0009741143 | AB29: 4.938412e-02 | AC29: 6.949721e-03
U30: [6,] | V30: 0.60951458 | W30: 0.1702024 | X30: 0.0050650509 | Y30: 7.209760e-02 | Z30: 3.529714e-03 | AA30: 0.0805407053 | AB30: 5.707991e-02 | AC30: 1.969997e-03
B31: 9.594835 | C31: 9.878014 | D31: 7.499322 | E31: 10.582777 | F31: 37.817285 | G31: 3.732949 | H31: 3.357207 | I31: 8.340225 | J31: 9.197386 | U31: [7,] | V31: 0.5584548 | W31: 1.421714e-05 | X31: 0.0111942379 | Y31: 2.088411e-01 | Z31: 8.430947e-05 | AA31: 0.1963170699 | AB31: 2.379697e-02 | AC31: 1.297335e-03
U32: [8,] | V32: 0.6445767 | W32: 0.03645494 | X32: 0.1070283527 | Y32: 1.097034e-01 | Z32: 8.276069e-02 | AA32: 0.0142982320 | AB32: 5.724444e-04 | AC32: 4.605288e-03
B33: 2.3941037 | C33: 1.2742203 | D33: 1.6893208 | E33: 1.0342351 | F33: 0.0998822 | G33: 0.41042367 | H33: 0.06020776 | I33: 0.03760645 | U33: [9,] | V33: 0.26174228 | W33: 0.6007023 | X33: 0.0037553861 | Y33: 1.211013e-02 | Z33: 5.886914e-02 | AA33: 0.0607833830 | AB33: 1.791863e-04 | AC33: 1.858193e-03
U34: [10,] | V34: 0.12495549 | W34: 0.6582435 | X34: 0.1697724144 | Y34: 3.530040e-02 | Z34: 2.281529e-03 | AA34: 0.0091515820 | AB34: 2.685019e-04 | AC34: 2.653458e-05
U35: [11,] | V35: 0.41408575 | W35: 0.02242099 | X35: 0.2468815330 | Y35: 2.459116e-01 | Z35: 3.183626e-03 | AA35: 0.0447545156 | AB35: 2.112767e-02 | AC35: 1.634294e-03
B36: 3.9454912 | C36: 4.0105365 | D36: 2.1968929 | E36: 9.0885814 | F36: 1.1803259 | G36: 1.9499294 | H36: 3.7716941 | I36: 7.5442128 | J36: 1.0943229 | K36: 8.6084047 | L36: 3.8651299 | M36: 15.826378 | N36: 3.0593139 | O36: 1.4036668 | P36: 0.8374632 | Q36: 21.721643 | R36: 9.896014 | U36: [12,] | V36: 0.61173764 | W36: 0.009853352 | X36: 0.3041324997 | Y36: 1.665650e-05 | Z36: 6.259903e-02 | AA36: 0.0114003598 | AB36: 2.348644e-04 | AC36: 2.559448e-05
U37: [13,] | V37: 0.29083268 | W37: 0.04204926 | X37: 0.5326157157 | Y37: 1.007844e-02 | Z37: 7.630726e-02 | AA37: 0.0367341342 | AB37: 5.186562e-05 | AC37: 1.133064e-02
U38: [14,] | V38: 0.53106908 | W38: 0.08956368 | X38: 0.0168419519 | Y38: 1.370940e-01 | Z38: 1.823355e-01 | AA38: 0.0005098100 | AB38: 3.824747e-02 | AC38: 4.338453e-03
U39: [15,] | V39: 0.64654307 | W39: 0.2318117 | X39: 0.0436992840 | Y39: 1.496247e-02 | Z39: 2.844846e-03 | AA39: 0.0008806385 | AB39: 1.518129e-02 | AC39: 4.407667e-02
B40: Donald Tusk | C40: 0.027646274 | D40: 0.45931882 | E40: 0.473538299 | F40: 0.016379740 | G40: 0.006183496 | H40: 0.0058217365 | I40: 0.0096833319 | J40: 1.428299e-03 | U40: [16,] | V40: 0.76612968 | W40: 0.1308923 | X40: 0.0949270644 | Y40: 2.654399e-05 | Z40: 5.390178e-04 | AA40: 0.0073871079 | AB40: 3.430210e-05 | AC40: 6.401503e-05
B41: Rafał Trzaskowski | C41: 0.61260862 | D41: 0.16847387 | E41: 0.008816274 | F41: 0.088140962 | G41: 0.001697181 | H41: 0.1139148262 | I41: 0.0063457565 | J41: 2.510066e-06 | U41: [17,] | V41: 0.53047858 | W41: 0.0122888 | X41: 0.1703242724 | Y41: 1.820519e-01 | Z41: 1.387083e-02 | AA41: 0.0902714112 | AB41: 7.096462e-04 | AC41: 4.605566e-06
...
